<?xml version="1.0" ?>
<sdf version="1.8">
    <world name="meu_mundo">
        <!--INICIO DOS PLUGINS DO MUNDO-->
        <plugin
            filename="ignition-gazebo-physics-system"
            name="ignition::gazebo::systems::Physics">
        </plugin>

        <plugin
            filename="ignition-gazebo-scene-broadcaster-system"
            name="ignition::gazebo::systems::SceneBroadcaster">
        </plugin>

        <physics name="1ms" type="ignored">
            <max_step_size>0.001</max_step_size>
            <real_time_factor>1.0</real_time_factor>
        </physics>
       
        <plugin
            filename="libignition-gazebo-user-commands-system.so"
            name="ignition::gazebo::systems::UserCommands">
        </plugin>

        <plugin filename="libignition-gazebo-triggered-publisher-system.so"
            name="ignition::gazebo::systems::TriggeredPublisher">
            <input type="ignition.msgs.Int32" topic="/keyboard/keypress">
                <match field="data">16777235</match>
            </input>
            <output type="ignition.msgs.Twist" topic="/cmd_vel">
                linear: {x: 0.5}, angular: {z: 0.0}
            </output>
        </plugin>
        
        <plugin filename="libignition-gazebo-triggered-publisher-system.so"
            name="ignition::gazebo::systems::TriggeredPublisher">
            <input type="ignition.msgs.Int32" topic="/keyboard/keypress">
                <match field="data">16777237</match>
            </input>
            <output type="ignition.msgs.Twist" topic="/cmd_vel">
                linear: {x: -0.5}, angular: {z: 0.0}
            </output>
        </plugin>

        <plugin filename="libignition-gazebo-triggered-publisher-system.so"
            name="ignition::gazebo::systems::TriggeredPublisher">
            <input type="ignition.msgs.Int32" topic="/keyboard/keypress">
                <match field="data">16777234</match>
            </input>
            <output type="ignition.msgs.Twist" topic="/cmd_vel">
                linear: {x: 0.0}, angular: {z: 0.5}
            </output>
        </plugin>

        <plugin filename="libignition-gazebo-triggered-publisher-system.so"
            name="ignition::gazebo::systems::TriggeredPublisher">
            <input type="ignition.msgs.Int32" topic="/keyboard/keypress">
                <match field="data">16777236</match>
            </input>
            <output type="ignition.msgs.Twist" topic="/cmd_vel">
                linear: {x: 0.0}, angular: {z: -0.5}
            </output>
        </plugin>

        <plugin filename="libignition-gazebo-imu-system.so"
            name="ignition::gazebo::systems::Imu">
        </plugin>

        <plugin filename="libignition-gazebo-contact-system.so"
            name="ignition::gazebo::systems::Contact">
        </plugin>

        <plugin
            filename="libignition-gazebo-sensors-system.so"
            name="ignition::gazebo::systems::Sensors">
            <render_engine>ogre2</render_engine>
        </plugin>
        <!--FIM DOS PLUGINS DO MUNDO-->
       

        <light type="directional" name="sun">
            <cast_shadows>true</cast_shadows>
            <pose>0 0 10 0 0 0</pose>
            <diffuse>0.8 0.8 0.8 1</diffuse>
            <specular>0.2 0.2 0.2 1</specular>
            <attenuation>
                <range>1000</range>
                <constant>0.9</constant>
                <linear>0.01</linear>
                <quadratic>0.001</quadratic>
            </attenuation>
            <direction>-0.5 0.1 -0.9</direction>
        </light>

        <model name="ground_plane">
            <static>true</static>
            <link name="link">
                <collision name="collision">
                <geometry>
                    <plane>
                    <normal>0 0 1</normal>
                    </plane>
                </geometry>
                </collision>
                <visual name="visual">
                <geometry>
                    <plane>
                    <normal>0 0 1</normal>
                    <size>100 100</size>
                    </plane>
                </geometry>
                <material>
                    <ambient>0.8 0.8 0.8 1</ambient>
                    <diffuse>0.8 0.8 0.8 1</diffuse>
                    <specular>0.8 0.8 0.8 1</specular>
                </material>
                </visual>
            </link>
        </model>

        <model name='wall'>
            <static>true</static>
            <pose>5 0 0 0 0 0</pose><!--pose relative to the world-->
            <plugin filename="libignition-gazebo-touchplugin-system.so"
                name="ignition::gazebo::systems::TouchPlugin">
                <target>meu_carrin</target>
                <namespace>wall</namespace>
                <time>0.001</time>
                <enabled>true</enabled>
                </plugin>
            <link name='box'>
                <pose/>
                <sensor name='sensor_contact' type='contact'>
                    <contact>
                        <collision>collision</collision>
                        </contact>
                </sensor>
                <visual name='visual'>
                    <geometry>
                        <box>
                            <size>0.5 10.0 2.0</size>
                        </box>
                    </geometry>
                    <material>
                        <ambient>0.0 0.0 1.0 1</ambient>
                        <diffuse>0.0 0.0 1.0 1</diffuse>
                        <specular>0.0 0.0 1.0 1</specular>
                    </material>
                </visual>
                <collision name='collision'>
                    <geometry>
                        <box>
                            <size>0.5 10.0 2.0</size>
                        </box>
                    </geometry>
                </collision>
            </link>
	    <plugin filename="gz-sim-touchplugin-system"
	    	    name="gz::sim::systems::TouchPlugin">
	        <target>vehicle_blue</target>
	        <namespace>wall</namespace>
	        <time>0.001</time>
	        <enabled>true</enabled>
	    </plugin>
        </model>

        <model name='wall2'>
	    <static>true</static>
	    <pose>-5 0 0 0 0 0</pose><!--pose relative to the world-->
	    <link name='box'>
	        <sensor name='sensor_contact' type='contact'>
		    <contact>
		        <collision>collision</collision>
		    </contact>
		</sensor>
	        <visual name='visual'>
	            <geometry>
	                <box>
	                    <size>0.5 10.0 2.0</size>
	                </box>
	            </geometry>
                <!--let's add color to our link-->
	            <material>
	                <ambient>0.0 0.0 1.0 1</ambient>
	                <diffuse>0.0 0.0 1.0 1</diffuse>
	                <specular>0.0 0.0 1.0 1</specular>
	            </material>
	        </visual>
	        <collision name='collision'>
	            <geometry>
	                <box>
	                    <size>0.5 10.0 2.0</size>
	                </box>
	            </geometry>
	        </collision>
	    </link>
	    <plugin filename="gz-sim-touchplugin-system"
	    	    name="gz::sim::systems::TouchPlugin">
	        <target>vehicle_blue</target>
	        <namespace>wall2</namespace>
	        <time>0.001</time>
	        <enabled>true</enabled>
	    </plugin>
	</model>


        <!--COMEÇO DO VEÍCULO + CHASSI-->
        <model name='meu_carrin' canonical_link='chassis'>
            <pose relative_to='world'>0 0 0.0 0 0 0</pose>
                <link name='chassis'>
                    <pose relative_to='__model__'>0.5 0 0.4 0 0 0</pose>
                    <inertial> <!--inertial properties of the link mass, inertia matix-->
                        <mass>1.14395</mass>
                        <inertia>
                            <ixx>0.095329</ixx>
                            <ixy>0</ixy>
                            <ixz>0</ixz>
                            <iyy>0.381317</iyy>
                            <iyz>0</iyz>
                            <izz>0.476646</izz>
                        </inertia>
                    </inertial>
                    <visual name='visual'>
                        <geometry>
                            <box>
                                <size>2.0 1.0 0.5</size>
                            </box>
                        </geometry>
                        <!--let's add color to our link-->
                        <material>
                            <ambient>0.0 1.0 0.0 1</ambient>
                            <diffuse>0.5 0.0 1.0 1</diffuse>
                            <specular>1.0 0.0 0.5 1</specular>
                        </material>
                    </visual>
                    <collision name='collision'>
                        <geometry>
                            <box>
                                <size>2.0 1.0 0.5</size>
                            </box>
                        </geometry>
                    </collision>

                    <sensor name="imu_sensor" type="imu">
                        <always_on>1</always_on>
                        <update_rate>1</update_rate>
                        <visualize>true</visualize>
                        <topic>imu</topic>
                    </sensor>

                    <sensor name='gpu_lidar' type='gpu_lidar'>"
			<pose relative_to='lidar_frame'>0 0 0 0 0 0</pose>
		        <topic>lidar</topic>
		        <update_rate>10</update_rate>
		        <ray>
			    <scan>
			        <horizontal>
		                    <samples>640</samples>
		                    <resolution>1</resolution>
		                    <min_angle>-1.396263</min_angle>
		                    <max_angle>1.396263</max_angle>
		                </horizontal>
		                <vertical>
		                    <samples>1</samples>
		                    <resolution>0.01</resolution>
		                    <min_angle>0</min_angle>
		                    <max_angle>0</max_angle>
		                </vertical>
		            </scan>
		            <range>
		                <min>0.08</min>
		                <max>10.0</max>
		                <resolution>0.01</resolution>
		            </range>
		        </ray>
		        <always_on>1</always_on>
		        <visualize>true</visualize>
		    </sensor>

                </link>

                <frame name="caster_frame" attached_to='chassis'>
                    <pose>0.8 0 -0.2 0 0 0</pose>
                </frame>

                <frame name="lidar_frame" attached_to='chassis'>
                    <pose>0.8 0 0.5 0 0 0</pose>
                </frame>
          
        <!--FIM DO CHASSI-->
          
        <!--COMEÇO DA CAMERA-->
            <link name="camera">
                <pose relative_to="chassis">1 0 0 0 0 0</pose>
                <visual name='visual'>
                    <geometry>
                        <box>
                            <size>0.1 0.1 0.1</size>
                        </box>
                    </geometry>
                    <material name="blue"/>
                </visual>
                <collision name='collision'>
                    <geometry>
                        <box>
                            <size>0.1 0.1 0.1</size>
                        </box>
                    </geometry>
                </collision>
                <inertial>
                    <mass>0.1</mass>
                    <inertia>
                        <ixx>0.043333</ixx>
                        <ixy>0</ixy>
                        <ixz>0</ixz>
                        <iyy>0.043333</iyy>
                        <iyz>0</iyz>
                        <izz>0.08</izz>
                    </inertia>
                </inertial>
            </link>
            
            <joint name='camera_joint' type="fixed">
                <origin xyz="1 0 0" rpy="0 0 0"/>
                <parent>chassis</parent>
                <child>camera</child>
            </joint>
            
            <gazebo reference="camera">
                <sensor type="camera" name="camera">
                    <update_rate>30.0</update_rate>
                    <camera name="head">
                        <horizontal_fov>1.3962634</horizontal_fov>
                        <image>
                            <width>800</width>
                            <height>800</height>
                            <format>R8G8B8</format>
                        </image>
                        <clip>
                            <near>0.02</near>
                            <far>300</far>
                        </clip>
                        <noise>
                            <type>gaussian</type>
                            <mean>0.0</mean>
                            <stddev>0.007</stddev>
                        </noise>
                    </camera>
                    <plugin name="camera_controller" filename="libgazebo_ros2_camera.so">
                        <alwaysOn>true</alwaysOn>
                        <updateRate>0.0</updateRate>
                        <cameraName>/carrin/camera</cameraName>
                        <imageTopicName>image_raw</imageTopicName>
                        <cameraInfoTopicName>Camera_info</cameraInfoTopicName>
                        <frameName>camera</frameName>
                        <hackBaseline>0.07</hackBaseline>
                        <distortionK1>0.0</distortionK1>
                        <distortionK2>0.0</distortionK2>
                        <distortionK3>0.0</distortionK3>
                        <distortionT1>0.0</distortionT1>
                        <distortionT2>0.0</distortionT2>
                    </plugin>
                </sensor>
            </gazebo>
            
        <!--FIM DA CAMERA-->
          
        <!--COMEÇO DAS RODAS-->
            <link name='roda_esquerda'>
                <pose relative_to="chassis">-0.7 0.6 0 -1.5707 0 0</pose>
                <inertial>
                    <mass>1</mass>
                    <inertia>
                        <ixx>0.043333</ixx>
                        <ixy>0</ixy>
                        <ixz>0</ixz>
                        <iyy>0.043333</iyy>
                        <iyz>0</iyz>
                        <izz>0.08</izz>
                    </inertia>
                </inertial>
                <visual name='visual'>
                    <geometry>
                        <cylinder>
                            <radius>0.4</radius>
                            <length>0.2</length>
                        </cylinder>
                    </geometry>
                    <material>
                        <ambient>1.0 0.0 0.0 1</ambient>
                        <diffuse>1.0 0.0 0.0 1</diffuse>
                        <specular>1.0 0.0 0.0 1</specular>
                    </material>
                </visual>
                <collision name='collision'>
                    <geometry>
                        <cylinder>
                            <radius>0.4</radius>
                            <length>0.2</length>
                        </cylinder>
                    </geometry>
                </collision>
            </link>

            <link name='roda_direita'>
                <pose relative_to="chassis">-0.7 -0.6 0 -1.5707 0 0</pose>
                <inertial>
                    <mass>1</mass>
                    <inertia>
                        <ixx>0.043333</ixx>
                        <ixy>0</ixy>
                        <ixz>0</ixz>
                        <iyy>0.043333</iyy>
                        <iyz>0</iyz>
                        <izz>0.08</izz>
                    </inertia>
                </inertial>
                <visual name='visual'>
                    <geometry>
                        <cylinder>
                            <radius>0.4</radius>
                            <length>0.2</length>
                        </cylinder>
                    </geometry>
                    <material>
                        <ambient>1.0 0.0 0.0 1</ambient>
                        <diffuse>1.0 0.0 0.0 1</diffuse>
                        <specular>1.0 0.0 0.0 1</specular>
                    </material>
                </visual>
                <collision name='collision'>
                    <geometry>
                        <cylinder>
                            <radius>0.4</radius>
                            <length>0.2</length>
                        </cylinder>
                    </geometry>
                </collision>
            </link>

            <link name='caster'>
                <pose relative_to='caster_frame'/>
                <inertial>
                    <mass>1</mass>
                    <inertia>
                        <ixx>0.016</ixx>
                        <ixy>0</ixy>
                        <ixz>0</ixz>
                        <iyy>0.016</iyy>
                        <iyz>0</iyz>
                        <izz>0.016</izz>
                    </inertia>
                </inertial>
                <visual name='visual'>
                    <geometry>
                        <sphere>
                            <radius>0.2</radius>
                        </sphere>
                    </geometry>
                    <material>
                        <ambient>0.0 1 0.0 1</ambient>
                        <diffuse>0.0 1 0.0 1</diffuse>
                        <specular>0.0 1 0.0 1</specular>
                    </material>
                </visual>
                <collision name='collision'>
                    <geometry>
                        <sphere>
                            <radius>0.2</radius>
                        </sphere>
                    </geometry>
                </collision>
            </link>
            
        <!--FIM DAS RODAS-->

        <!--COMEÇO DAS JUNTAS-->
            <joint name='junta_roda_esquerda' type='revolute'>
                <pose relative_to='roda_esquerda'/>
                <parent>chassis</parent>
                <child>roda_esquerda</child>
                <axis>
                    <xyz expressed_in='__model__'>0 1 0</xyz>
                    <limit>
                        <lower>-1.79769e+308</lower>   
                        <upper>1.79769e+308</upper>     
                    </limit>
                </axis>
            </joint>

            <joint name='junta_roda_direita' type='revolute'>
                <pose relative_to='roda_direita'/>
                <parent>chassis</parent>
                <child>roda_direita</child>
                <axis>
                    <xyz expressed_in='__model__'>0 1 0</xyz>
                    <limit>
                        <lower>-1.79769e+308</lower>   
                        <upper>1.79769e+308</upper>     
                    </limit>
                </axis>
            </joint>

            <joint name='caster_wheel' type='ball'>
                <parent>chassis</parent>
                <child>caster</child>
            </joint>
        <!--FIM DAS JUNTAS-->

        <!--INICIO DOS PLUGINS DO MODELO-->
            <plugin
                filename="libignition-gazebo-diff-drive-system.so"
                name="ignition::gazebo::systems::DiffDrive">
                <left_joint>junta_roda_esquerda</left_joint>
                <right_joint>junta_roda_direita</right_joint>
                <wheel_separation>1.2</wheel_separation>
                <wheel_radius>0.4</wheel_radius>
                <odom_publish_frequency>1</odom_publish_frequency>
                <topic>cmd_vel</topic>
            </plugin>

            <plugin filename="libignition-gazebo-triggered-publisher-system.so"
                name="ignition::gazebo::systems::TriggeredPublisher">
                <input type="ignition.msgs.Boolean" topic="/wall/touched">
                    <match>data: true</match>
                </input>
                <output type="ignition.msgs.Twist" topic="/cmd_vel">
                    linear: {x: 0.0}, angular: {z: 0.0}
                </output>
            </plugin>
            
        <!--FIM DOS PLUGINS DO MODELO-->  
        </model>
    </world>
</sdf>
